{
 "cells": [
  {
   "cell_type": "code",
   "execution_count": 1,
   "id": "e5a7209e",
   "metadata": {},
   "outputs": [],
   "source": [
    "import tensorflow as tf\n",
    "from tensorflow.keras.preprocessing.image import ImageDataGenerator"
   ]
  },
  {
   "cell_type": "code",
   "execution_count": 2,
   "id": "a17846b6",
   "metadata": {},
   "outputs": [],
   "source": [
    "# Set up the train and test data generators\n",
    "train_datagen = ImageDataGenerator(rescale=1./255)\n",
    "test_datagen = ImageDataGenerator(rescale=1./255)"
   ]
  },
  {
   "cell_type": "code",
   "execution_count": 3,
   "id": "cd8ee3c1",
   "metadata": {},
   "outputs": [
    {
     "name": "stdout",
     "output_type": "stream",
     "text": [
      "Found 12000 images belonging to 4 classes.\n"
     ]
    }
   ],
   "source": [
    "# Create training dataset\n",
    "train_generator = train_datagen.flow_from_directory(\n",
    "        \"Data_4class\\\\Data_4class\\\\train\",\n",
    "        target_size=(224, 224),\n",
    "        batch_size=32,\n",
    "        class_mode='categorical')"
   ]
  },
  {
   "cell_type": "code",
   "execution_count": 4,
   "id": "83d13c04",
   "metadata": {},
   "outputs": [
    {
     "name": "stdout",
     "output_type": "stream",
     "text": [
      "Found 400 images belonging to 4 classes.\n"
     ]
    }
   ],
   "source": [
    "# Create validation dataset\n",
    "validation_generator = test_datagen.flow_from_directory(\n",
    "        \"Data_4class\\\\Data_4class\\\\test\",\n",
    "        target_size=(224, 224),\n",
    "        batch_size=32,\n",
    "        class_mode='categorical')"
   ]
  },
  {
   "cell_type": "code",
   "execution_count": 5,
   "id": "8f3898a6",
   "metadata": {},
   "outputs": [],
   "source": [
    "# Define the model architecture\n",
    "model = tf.keras.models.Sequential([\n",
    "    tf.keras.layers.Conv2D(40, (3,3), activation='relu', input_shape=(224, 224, 3)),\n",
    "    tf.keras.layers.MaxPooling2D(2, 2),\n",
    "    tf.keras.layers.Conv2D(64, (3,3), activation='relu'),\n",
    "    tf.keras.layers.MaxPooling2D(2,2),\n",
    "    tf.keras.layers.Conv2D(128, (3,3), activation='relu'),\n",
    "    tf.keras.layers.MaxPooling2D(2,2),\n",
    "    tf.keras.layers.Flatten(),\n",
    "    tf.keras.layers.Dense(128, activation='relu'),\n",
    "    tf.keras.layers.Dense(4, activation='softmax')\n",
    "])"
   ]
  },
  {
   "cell_type": "code",
   "execution_count": 6,
   "id": "bdfb7598",
   "metadata": {},
   "outputs": [],
   "source": [
    "# Compile the model with appropriate loss function and optimizer\n",
    "model.compile(loss='categorical_crossentropy',\n",
    "              optimizer=tf.keras.optimizers.Adam(),\n",
    "              metrics=['accuracy'])"
   ]
  },
  {
   "cell_type": "code",
   "execution_count": 7,
   "id": "bab17b94",
   "metadata": {},
   "outputs": [
    {
     "name": "stdout",
     "output_type": "stream",
     "text": [
      "Epoch 1/10\n",
      "375/375 [==============================] - 487s 1s/step - loss: 0.0366 - accuracy: 0.9892 - val_loss: 5.8200e-06 - val_accuracy: 1.0000\n",
      "Epoch 2/10\n",
      "375/375 [==============================] - 467s 1s/step - loss: 5.8506e-06 - accuracy: 1.0000 - val_loss: 2.9582e-06 - val_accuracy: 1.0000\n",
      "Epoch 3/10\n",
      "375/375 [==============================] - 495s 1s/step - loss: 2.6463e-06 - accuracy: 1.0000 - val_loss: 1.4362e-06 - val_accuracy: 1.0000\n",
      "Epoch 4/10\n",
      "375/375 [==============================] - 522s 1s/step - loss: 1.4903e-06 - accuracy: 1.0000 - val_loss: 8.8543e-07 - val_accuracy: 1.0000\n",
      "Epoch 5/10\n",
      "375/375 [==============================] - 484s 1s/step - loss: 9.3278e-07 - accuracy: 1.0000 - val_loss: 6.1899e-07 - val_accuracy: 1.0000\n",
      "Epoch 6/10\n",
      "375/375 [==============================] - 443s 1s/step - loss: 6.2821e-07 - accuracy: 1.0000 - val_loss: 4.3541e-07 - val_accuracy: 1.0000\n",
      "Epoch 7/10\n",
      "375/375 [==============================] - 449s 1s/step - loss: 4.4114e-07 - accuracy: 1.0000 - val_loss: 3.1292e-07 - val_accuracy: 1.0000\n",
      "Epoch 8/10\n",
      "375/375 [==============================] - 448s 1s/step - loss: 3.2212e-07 - accuracy: 1.0000 - val_loss: 2.3514e-07 - val_accuracy: 1.0000\n",
      "Epoch 9/10\n",
      "375/375 [==============================] - 435s 1s/step - loss: 2.4000e-07 - accuracy: 1.0000 - val_loss: 1.8150e-07 - val_accuracy: 1.0000\n",
      "Epoch 10/10\n",
      "375/375 [==============================] - 418s 1s/step - loss: 1.8139e-07 - accuracy: 1.0000 - val_loss: 1.4156e-07 - val_accuracy: 1.0000\n"
     ]
    }
   ],
   "source": [
    "# Train the model on the training data\n",
    "history = model.fit(\n",
    "      train_generator,\n",
    "      steps_per_epoch=train_generator.samples/train_generator.batch_size,\n",
    "      epochs=10,\n",
    "      validation_data=validation_generator,\n",
    "      validation_steps=validation_generator.samples/validation_generator.batch_size,\n",
    "      verbose=1)"
   ]
  },
  {
   "cell_type": "code",
   "execution_count": 8,
   "id": "e2404479",
   "metadata": {},
   "outputs": [
    {
     "name": "stdout",
     "output_type": "stream",
     "text": [
      "WARNING:tensorflow:Model was constructed with shape (None, 224, 224, 3) for input KerasTensor(type_spec=TensorSpec(shape=(None, 224, 224, 3), dtype=tf.float32, name='conv2d_input'), name='conv2d_input', description=\"created by layer 'conv2d_input'\"), but it was called on an input with incompatible shape (None, 224, 224, 1).\n"
     ]
    },
    {
     "ename": "ValueError",
     "evalue": "in user code:\n\n    File \"C:\\Users\\Manish_Bhoge\\Anaconda3\\lib\\site-packages\\keras\\engine\\training.py\", line 2041, in predict_function  *\n        return step_function(self, iterator)\n    File \"C:\\Users\\Manish_Bhoge\\Anaconda3\\lib\\site-packages\\keras\\engine\\training.py\", line 2027, in step_function  **\n        outputs = model.distribute_strategy.run(run_step, args=(data,))\n    File \"C:\\Users\\Manish_Bhoge\\Anaconda3\\lib\\site-packages\\keras\\engine\\training.py\", line 2015, in run_step  **\n        outputs = model.predict_step(data)\n    File \"C:\\Users\\Manish_Bhoge\\Anaconda3\\lib\\site-packages\\keras\\engine\\training.py\", line 1983, in predict_step\n        return self(x, training=False)\n    File \"C:\\Users\\Manish_Bhoge\\Anaconda3\\lib\\site-packages\\keras\\utils\\traceback_utils.py\", line 70, in error_handler\n        raise e.with_traceback(filtered_tb) from None\n    File \"C:\\Users\\Manish_Bhoge\\Anaconda3\\lib\\site-packages\\keras\\engine\\input_spec.py\", line 277, in assert_input_compatibility\n        raise ValueError(\n\n    ValueError: Exception encountered when calling layer \"sequential\" \"                 f\"(type Sequential).\n    \n    Input 0 of layer \"conv2d\" is incompatible with the layer: expected axis -1 of input shape to have value 3, but received input with shape (None, 224, 224, 1)\n    \n    Call arguments received by layer \"sequential\" \"                 f\"(type Sequential):\n      • inputs=tf.Tensor(shape=(None, 224, 224, 1), dtype=float32)\n      • training=False\n      • mask=None\n",
     "output_type": "error",
     "traceback": [
      "\u001b[1;31m---------------------------------------------------------------------------\u001b[0m",
      "\u001b[1;31mValueError\u001b[0m                                Traceback (most recent call last)",
      "Input \u001b[1;32mIn [8]\u001b[0m, in \u001b[0;36m<cell line: 6>\u001b[1;34m()\u001b[0m\n\u001b[0;32m      9\u001b[0m img_array \u001b[38;5;241m=\u001b[39m tf\u001b[38;5;241m.\u001b[39mkeras\u001b[38;5;241m.\u001b[39mpreprocessing\u001b[38;5;241m.\u001b[39mimage\u001b[38;5;241m.\u001b[39mimg_to_array(img)\n\u001b[0;32m     10\u001b[0m img_array \u001b[38;5;241m=\u001b[39m tf\u001b[38;5;241m.\u001b[39mexpand_dims(img_array, \u001b[38;5;241m0\u001b[39m) \n\u001b[1;32m---> 11\u001b[0m predictions \u001b[38;5;241m=\u001b[39m \u001b[43mmodel\u001b[49m\u001b[38;5;241;43m.\u001b[39;49m\u001b[43mpredict\u001b[49m\u001b[43m(\u001b[49m\u001b[43mimg_array\u001b[49m\u001b[43m)\u001b[49m\n\u001b[0;32m     12\u001b[0m predicted_class \u001b[38;5;241m=\u001b[39m tf\u001b[38;5;241m.\u001b[39margmax(predictions[\u001b[38;5;241m0\u001b[39m])\u001b[38;5;241m.\u001b[39mnumpy()\n\u001b[0;32m     13\u001b[0m \u001b[38;5;28;01mif\u001b[39;00m predicted_class \u001b[38;5;241m==\u001b[39m \u001b[38;5;241m0\u001b[39m:\n",
      "File \u001b[1;32m~\\Anaconda3\\lib\\site-packages\\keras\\utils\\traceback_utils.py:70\u001b[0m, in \u001b[0;36mfilter_traceback.<locals>.error_handler\u001b[1;34m(*args, **kwargs)\u001b[0m\n\u001b[0;32m     67\u001b[0m     filtered_tb \u001b[38;5;241m=\u001b[39m _process_traceback_frames(e\u001b[38;5;241m.\u001b[39m__traceback__)\n\u001b[0;32m     68\u001b[0m     \u001b[38;5;66;03m# To get the full stack trace, call:\u001b[39;00m\n\u001b[0;32m     69\u001b[0m     \u001b[38;5;66;03m# `tf.debugging.disable_traceback_filtering()`\u001b[39;00m\n\u001b[1;32m---> 70\u001b[0m     \u001b[38;5;28;01mraise\u001b[39;00m e\u001b[38;5;241m.\u001b[39mwith_traceback(filtered_tb) \u001b[38;5;28;01mfrom\u001b[39;00m \u001b[38;5;28mNone\u001b[39m\n\u001b[0;32m     71\u001b[0m \u001b[38;5;28;01mfinally\u001b[39;00m:\n\u001b[0;32m     72\u001b[0m     \u001b[38;5;28;01mdel\u001b[39;00m filtered_tb\n",
      "File \u001b[1;32mC:\\Users\\MANISH~1\\AppData\\Local\\Temp\\__autograph_generated_filel__fjkyw.py:15\u001b[0m, in \u001b[0;36mouter_factory.<locals>.inner_factory.<locals>.tf__predict_function\u001b[1;34m(iterator)\u001b[0m\n\u001b[0;32m     13\u001b[0m \u001b[38;5;28;01mtry\u001b[39;00m:\n\u001b[0;32m     14\u001b[0m     do_return \u001b[38;5;241m=\u001b[39m \u001b[38;5;28;01mTrue\u001b[39;00m\n\u001b[1;32m---> 15\u001b[0m     retval_ \u001b[38;5;241m=\u001b[39m ag__\u001b[38;5;241m.\u001b[39mconverted_call(ag__\u001b[38;5;241m.\u001b[39mld(step_function), (ag__\u001b[38;5;241m.\u001b[39mld(\u001b[38;5;28mself\u001b[39m), ag__\u001b[38;5;241m.\u001b[39mld(iterator)), \u001b[38;5;28;01mNone\u001b[39;00m, fscope)\n\u001b[0;32m     16\u001b[0m \u001b[38;5;28;01mexcept\u001b[39;00m:\n\u001b[0;32m     17\u001b[0m     do_return \u001b[38;5;241m=\u001b[39m \u001b[38;5;28;01mFalse\u001b[39;00m\n",
      "\u001b[1;31mValueError\u001b[0m: in user code:\n\n    File \"C:\\Users\\Manish_Bhoge\\Anaconda3\\lib\\site-packages\\keras\\engine\\training.py\", line 2041, in predict_function  *\n        return step_function(self, iterator)\n    File \"C:\\Users\\Manish_Bhoge\\Anaconda3\\lib\\site-packages\\keras\\engine\\training.py\", line 2027, in step_function  **\n        outputs = model.distribute_strategy.run(run_step, args=(data,))\n    File \"C:\\Users\\Manish_Bhoge\\Anaconda3\\lib\\site-packages\\keras\\engine\\training.py\", line 2015, in run_step  **\n        outputs = model.predict_step(data)\n    File \"C:\\Users\\Manish_Bhoge\\Anaconda3\\lib\\site-packages\\keras\\engine\\training.py\", line 1983, in predict_step\n        return self(x, training=False)\n    File \"C:\\Users\\Manish_Bhoge\\Anaconda3\\lib\\site-packages\\keras\\utils\\traceback_utils.py\", line 70, in error_handler\n        raise e.with_traceback(filtered_tb) from None\n    File \"C:\\Users\\Manish_Bhoge\\Anaconda3\\lib\\site-packages\\keras\\engine\\input_spec.py\", line 277, in assert_input_compatibility\n        raise ValueError(\n\n    ValueError: Exception encountered when calling layer \"sequential\" \"                 f\"(type Sequential).\n    \n    Input 0 of layer \"conv2d\" is incompatible with the layer: expected axis -1 of input shape to have value 3, but received input with shape (None, 224, 224, 1)\n    \n    Call arguments received by layer \"sequential\" \"                 f\"(type Sequential):\n      • inputs=tf.Tensor(shape=(None, 224, 224, 1), dtype=float32)\n      • training=False\n      • mask=None\n"
     ]
    }
   ],
   "source": [
    "import os\n",
    "from PIL import Image\n",
    "\n",
    "validation_path = 'Data_4Class\\\\Data_4Class\\\\inference'\n",
    "\n",
    "for filename in os.listdir(validation_path):\n",
    "    img = Image.open(os.path.join(validation_path, filename))\n",
    "    img = img.resize((224, 224))\n",
    "    img_array = tf.keras.preprocessing.image.img_to_array(img)\n",
    "    img_array = tf.expand_dims(img_array, 0) \n",
    "    predictions = model.predict(img_array)\n",
    "    predicted_class = tf.argmax(predictions[0]).numpy()\n",
    "    if predicted_class == 0:\n",
    "        print(filename, \"- Circle\")\n",
    "    elif predicted_class == 1:\n",
    "        print(filename, \"- Square\")\n",
    "    elif predicted_class == 2:\n",
    "        print(filename, \"- Star\")\n",
    "    else:\n",
    "        print(filename, \"- Triangle\")"
   ]
  },
  {
   "cell_type": "code",
   "execution_count": null,
   "id": "ccd54bd5",
   "metadata": {},
   "outputs": [],
   "source": []
  }
 ],
 "metadata": {
  "kernelspec": {
   "display_name": "Python 3 (ipykernel)",
   "language": "python",
   "name": "python3"
  },
  "language_info": {
   "codemirror_mode": {
    "name": "ipython",
    "version": 3
   },
   "file_extension": ".py",
   "mimetype": "text/x-python",
   "name": "python",
   "nbconvert_exporter": "python",
   "pygments_lexer": "ipython3",
   "version": "3.9.12"
  }
 },
 "nbformat": 4,
 "nbformat_minor": 5
}
